2025-06-22 13:31:09,551 INFO    Thread-8 (_run_job):501119 [wandb_setup.py:_flush():70] Current SDK version is 0.19.11
2025-06-22 13:31:09,551 INFO    Thread-8 (_run_job):501119 [wandb_setup.py:_flush():70] Configure stats pid to 501119
2025-06-22 13:31:09,551 INFO    Thread-8 (_run_job):501119 [wandb_setup.py:_flush():70] Loading settings from /home/cagri/.config/wandb/settings
2025-06-22 13:31:09,551 INFO    Thread-8 (_run_job):501119 [wandb_setup.py:_flush():70] Loading settings from /home/cagri/Desktop/IS-584-Term-Project/wandb/settings
2025-06-22 13:31:09,551 INFO    Thread-8 (_run_job):501119 [wandb_setup.py:_flush():70] Loading settings from environment variables
2025-06-22 13:31:09,551 INFO    Thread-8 (_run_job):501119 [wandb_init.py:setup_run_log_directory():724] Logging user logs to /home/cagri/Desktop/IS-584-Term-Project/wandb/run-20250622_133109-4nsis2ew/logs/debug.log
2025-06-22 13:31:09,551 INFO    Thread-8 (_run_job):501119 [wandb_init.py:setup_run_log_directory():725] Logging internal logs to /home/cagri/Desktop/IS-584-Term-Project/wandb/run-20250622_133109-4nsis2ew/logs/debug-internal.log
2025-06-22 13:31:09,551 INFO    Thread-8 (_run_job):501119 [wandb_init.py:monkeypatch_ipython():643] configuring jupyter hooks <wandb.sdk.wandb_init._WandbInit object at 0x738e36b73ce0>
2025-06-22 13:31:09,551 INFO    Thread-8 (_run_job):501119 [wandb_init.py:init():852] calling init triggers
2025-06-22 13:31:09,551 INFO    Thread-8 (_run_job):501119 [wandb_init.py:init():857] wandb.init called with sweep_config: {'lora_alpha': 16, 'lora_dropout': 0.05, 'max_length': 512, 'n_shots': 2, 'r': 2}
config: {'_wandb': {}}
2025-06-22 13:31:09,551 INFO    Thread-8 (_run_job):501119 [wandb_init.py:init():893] starting backend
2025-06-22 13:31:09,551 INFO    Thread-8 (_run_job):501119 [wandb_init.py:init():897] sending inform_init request
2025-06-22 13:31:09,553 INFO    Thread-8 (_run_job):501119 [backend.py:_multiprocessing_setup():101] multiprocessing start_methods=fork,spawn,forkserver, using: spawn
2025-06-22 13:31:09,553 INFO    Thread-8 (_run_job):501119 [wandb_init.py:init():907] backend started and connected
2025-06-22 13:31:09,554 INFO    Thread-8 (_run_job):501119 [wandb_run.py:_config_callback():1436] config_cb None None {'lora_alpha': 16, 'lora_dropout': 0.05, 'max_length': 512, 'n_shots': 2, 'r': 2}
2025-06-22 13:31:09,555 INFO    Thread-8 (_run_job):501119 [wandb_run.py:_label_probe_notebook():1376] probe notebook
2025-06-22 13:31:09,556 INFO    Thread-8 (_run_job):501119 [wandb_init.py:init():1005] updated telemetry
2025-06-22 13:31:09,559 INFO    Thread-8 (_run_job):501119 [wandb_init.py:init():1029] communicating run to backend with 90.0 second timeout
2025-06-22 13:31:10,156 INFO    Thread-8 (_run_job):501119 [wandb_init.py:init():1104] starting run threads in backend
2025-06-22 13:31:10,248 INFO    Thread-8 (_run_job):501119 [wandb_run.py:_console_start():2573] atexit reg
2025-06-22 13:31:10,249 INFO    Thread-8 (_run_job):501119 [wandb_run.py:_redirect():2421] redirect: wrap_raw
2025-06-22 13:31:10,249 INFO    Thread-8 (_run_job):501119 [wandb_run.py:_redirect():2490] Wrapping output streams.
2025-06-22 13:31:10,249 INFO    Thread-8 (_run_job):501119 [wandb_run.py:_redirect():2513] Redirects installed.
2025-06-22 13:31:10,250 INFO    Thread-8 (_run_job):501119 [wandb_init.py:init():1150] run started, returning control to user process
2025-06-22 13:46:06,874 INFO    MainThread:501119 [wandb_init.py:_post_run_cell_hook():613] [no run ID] resuming backend
2025-06-22 13:46:07,271 INFO    MsgRouterThr:501119 [mailbox.py:close():129] [no run ID] Closing mailbox, abandoning 1 handles.
2025-06-22 13:46:07,498 INFO    Thread-8 (_run_job):501119 [wandb_run.py:_finish():2321] finishing run e274028-metu-middle-east-technical-university/tinyllama-fewshot/4nsis2ew
2025-06-22 13:46:07,498 INFO    Thread-8 (_run_job):501119 [jupyter.py:save_history():477] not saving jupyter history
2025-06-22 13:46:07,498 INFO    Thread-8 (_run_job):501119 [jupyter.py:save_ipynb():401] not saving jupyter notebook
2025-06-22 13:46:07,498 INFO    Thread-8 (_run_job):501119 [wandb_init.py:_jupyter_teardown():628] cleaning up jupyter logic
2025-06-22 13:46:07,499 INFO    Thread-8 (_run_job):501119 [wandb_run.py:_atexit_cleanup():2538] got exitcode: 1
2025-06-22 13:46:07,499 INFO    Thread-8 (_run_job):501119 [wandb_run.py:_restore():2520] restore
2025-06-22 13:46:07,499 INFO    Thread-8 (_run_job):501119 [wandb_run.py:_restore():2526] restore done
2025-06-22 13:46:07,499 INFO    Thread-8 (_run_job):501119 [wandb_run.py:_restore():2520] restore
2025-06-22 13:46:07,499 INFO    Thread-8 (_run_job):501119 [wandb_run.py:_restore():2526] restore done
2025-06-22 13:46:07,499 ERROR   Thread-8 (_run_job):501119 [wandb_run.py:_atexit_cleanup():2559] Problem finishing run
Traceback (most recent call last):
  File "/home/cagri/.local/lib/python3.12/site-packages/wandb/agents/pyagent.py", line 306, in _run_job
    self._function()
  File "/tmp/ipykernel_501119/2108634327.py", line 111, in sweep_prompt_eval
    evaluate(test_dataset, model, tokenizer, name="Test")
  File "/tmp/ipykernel_501119/2108634327.py", line 53, in evaluate
    print(f"\nGenerated:\n{output_text}")
  File "/home/cagri/.local/lib/python3.12/site-packages/ipykernel/iostream.py", line 694, in write
    self._schedule_flush()
  File "/home/cagri/.local/lib/python3.12/site-packages/ipykernel/iostream.py", line 590, in _schedule_flush
    self.pub_thread.schedule(_schedule_in_thread)
  File "/home/cagri/.local/lib/python3.12/site-packages/ipykernel/iostream.py", line 267, in schedule
    self._event_pipe.send(b"")
  File "/home/cagri/.local/lib/python3.12/site-packages/zmq/sugar/socket.py", line 698, in send
    return super().send(data, flags=flags, copy=copy, track=track)
           ^^^^^^^^^^^^^^^^^^^^^^^^^^^^^^^^^^^^^^^^^^^^^^^^^^^^^^^
  File "_zmq.py", line 1081, in zmq.backend.cython._zmq.Socket.send
  File "_zmq.py", line 1123, in zmq.backend.cython._zmq.Socket.send
  File "_zmq.py", line 1268, in zmq.backend.cython._zmq._check_closed
zmq.error.ZMQError: Socket operation on non-socket

During handling of the above exception, another exception occurred:

Traceback (most recent call last):
  File "/home/cagri/.local/lib/python3.12/site-packages/wandb/sdk/wandb_run.py", line 2550, in _atexit_cleanup
    self._on_finish()
  File "/home/cagri/.local/lib/python3.12/site-packages/wandb/sdk/wandb_run.py", line 2797, in _on_finish
    exit_handle = self._backend.interface.deliver_exit(self._exit_code)
                  ^^^^^^^^^^^^^^^^^^^^^^^^^^^^^^^^^^^^^^^^^^^^^^^^^^^^^
  File "/home/cagri/.local/lib/python3.12/site-packages/wandb/sdk/interface/interface.py", line 1005, in deliver_exit
    return self._deliver_exit(exit_data)
           ^^^^^^^^^^^^^^^^^^^^^^^^^^^^^
  File "/home/cagri/.local/lib/python3.12/site-packages/wandb/sdk/interface/interface_shared.py", line 436, in _deliver_exit
    return self._deliver_record(record)
           ^^^^^^^^^^^^^^^^^^^^^^^^^^^^
  File "/home/cagri/.local/lib/python3.12/site-packages/wandb/sdk/interface/interface_shared.py", line 389, in _deliver_record
    handle = mailbox.require_response(record)
             ^^^^^^^^^^^^^^^^^^^^^^^^^^^^^^^^
  File "/home/cagri/.local/lib/python3.12/site-packages/wandb/sdk/mailbox/mailbox.py", line 68, in require_response
    raise MailboxClosedError()
wandb.sdk.mailbox.mailbox.MailboxClosedError
