2025-06-22 16:42:43,876 INFO    Thread-8 (_run_job):585317 [wandb_setup.py:_flush():70] Current SDK version is 0.19.11
2025-06-22 16:42:43,876 INFO    Thread-8 (_run_job):585317 [wandb_setup.py:_flush():70] Configure stats pid to 585317
2025-06-22 16:42:43,876 INFO    Thread-8 (_run_job):585317 [wandb_setup.py:_flush():70] Loading settings from /home/cagri/.config/wandb/settings
2025-06-22 16:42:43,876 INFO    Thread-8 (_run_job):585317 [wandb_setup.py:_flush():70] Loading settings from /home/cagri/Desktop/IS-584-Term-Project/wandb/settings
2025-06-22 16:42:43,876 INFO    Thread-8 (_run_job):585317 [wandb_setup.py:_flush():70] Loading settings from environment variables
2025-06-22 16:42:43,876 INFO    Thread-8 (_run_job):585317 [wandb_init.py:setup_run_log_directory():724] Logging user logs to /home/cagri/Desktop/IS-584-Term-Project/wandb/run-20250622_164243-bi9lvl2e/logs/debug.log
2025-06-22 16:42:43,876 INFO    Thread-8 (_run_job):585317 [wandb_init.py:setup_run_log_directory():725] Logging internal logs to /home/cagri/Desktop/IS-584-Term-Project/wandb/run-20250622_164243-bi9lvl2e/logs/debug-internal.log
2025-06-22 16:42:43,876 INFO    Thread-8 (_run_job):585317 [wandb_init.py:monkeypatch_ipython():643] configuring jupyter hooks <wandb.sdk.wandb_init._WandbInit object at 0x70f5c9abbce0>
2025-06-22 16:42:43,876 INFO    Thread-8 (_run_job):585317 [wandb_init.py:init():852] calling init triggers
2025-06-22 16:42:43,876 INFO    Thread-8 (_run_job):585317 [wandb_init.py:init():857] wandb.init called with sweep_config: {'lora_alpha': 16, 'lora_dropout': 0.05, 'max_length': 1024, 'n_shots': 1, 'r': 2}
config: {'_wandb': {}}
2025-06-22 16:42:43,876 INFO    Thread-8 (_run_job):585317 [wandb_init.py:init():893] starting backend
2025-06-22 16:42:43,876 INFO    Thread-8 (_run_job):585317 [wandb_init.py:init():897] sending inform_init request
2025-06-22 16:42:43,878 INFO    Thread-8 (_run_job):585317 [backend.py:_multiprocessing_setup():101] multiprocessing start_methods=fork,spawn,forkserver, using: spawn
2025-06-22 16:42:43,878 INFO    Thread-8 (_run_job):585317 [wandb_init.py:init():907] backend started and connected
2025-06-22 16:42:43,879 INFO    Thread-8 (_run_job):585317 [wandb_run.py:_config_callback():1436] config_cb None None {'lora_alpha': 16, 'lora_dropout': 0.05, 'max_length': 1024, 'n_shots': 1, 'r': 2}
2025-06-22 16:42:43,880 INFO    Thread-8 (_run_job):585317 [wandb_run.py:_label_probe_notebook():1376] probe notebook
2025-06-22 16:42:43,880 INFO    Thread-8 (_run_job):585317 [wandb_init.py:init():1005] updated telemetry
2025-06-22 16:42:43,883 INFO    Thread-8 (_run_job):585317 [wandb_init.py:init():1029] communicating run to backend with 90.0 second timeout
2025-06-22 16:42:44,504 INFO    Thread-8 (_run_job):585317 [wandb_init.py:init():1104] starting run threads in backend
2025-06-22 16:42:44,603 INFO    Thread-8 (_run_job):585317 [wandb_run.py:_console_start():2573] atexit reg
2025-06-22 16:42:44,604 INFO    Thread-8 (_run_job):585317 [wandb_run.py:_redirect():2421] redirect: wrap_raw
2025-06-22 16:42:44,604 INFO    Thread-8 (_run_job):585317 [wandb_run.py:_redirect():2490] Wrapping output streams.
2025-06-22 16:42:44,604 INFO    Thread-8 (_run_job):585317 [wandb_run.py:_redirect():2513] Redirects installed.
2025-06-22 16:42:44,605 INFO    Thread-8 (_run_job):585317 [wandb_init.py:init():1150] run started, returning control to user process
2025-06-22 19:39:28,132 INFO    Thread-7 (_heartbeat):585317 [retry.py:__call__():175] [no run ID] Retry attempt failed:
Traceback (most recent call last):
  File "/home/cagri/.local/lib/python3.12/site-packages/urllib3/connection.py", line 198, in _new_conn
    sock = connection.create_connection(
           ^^^^^^^^^^^^^^^^^^^^^^^^^^^^^
  File "/home/cagri/.local/lib/python3.12/site-packages/urllib3/util/connection.py", line 85, in create_connection
    raise err
  File "/home/cagri/.local/lib/python3.12/site-packages/urllib3/util/connection.py", line 73, in create_connection
    sock.connect(sa)
OSError: [Errno 101] Network is unreachable

The above exception was the direct cause of the following exception:

Traceback (most recent call last):
  File "/home/cagri/.local/lib/python3.12/site-packages/urllib3/connectionpool.py", line 787, in urlopen
    response = self._make_request(
               ^^^^^^^^^^^^^^^^^^^
  File "/home/cagri/.local/lib/python3.12/site-packages/urllib3/connectionpool.py", line 488, in _make_request
    raise new_e
  File "/home/cagri/.local/lib/python3.12/site-packages/urllib3/connectionpool.py", line 464, in _make_request
    self._validate_conn(conn)
  File "/home/cagri/.local/lib/python3.12/site-packages/urllib3/connectionpool.py", line 1093, in _validate_conn
    conn.connect()
  File "/home/cagri/.local/lib/python3.12/site-packages/urllib3/connection.py", line 704, in connect
    self.sock = sock = self._new_conn()
                       ^^^^^^^^^^^^^^^^
  File "/home/cagri/.local/lib/python3.12/site-packages/urllib3/connection.py", line 213, in _new_conn
    raise NewConnectionError(
urllib3.exceptions.NewConnectionError: <urllib3.connection.HTTPSConnection object at 0x70f5acfdc440>: Failed to establish a new connection: [Errno 101] Network is unreachable

The above exception was the direct cause of the following exception:

Traceback (most recent call last):
  File "/home/cagri/.local/lib/python3.12/site-packages/requests/adapters.py", line 667, in send
    resp = conn.urlopen(
           ^^^^^^^^^^^^^
  File "/home/cagri/.local/lib/python3.12/site-packages/urllib3/connectionpool.py", line 841, in urlopen
    retries = retries.increment(
              ^^^^^^^^^^^^^^^^^^
  File "/home/cagri/.local/lib/python3.12/site-packages/urllib3/util/retry.py", line 519, in increment
    raise MaxRetryError(_pool, url, reason) from reason  # type: ignore[arg-type]
    ^^^^^^^^^^^^^^^^^^^^^^^^^^^^^^^^^^^^^^^^^^^^^^^^^^^
urllib3.exceptions.MaxRetryError: HTTPSConnectionPool(host='api.wandb.ai', port=443): Max retries exceeded with url: /graphql (Caused by NewConnectionError('<urllib3.connection.HTTPSConnection object at 0x70f5acfdc440>: Failed to establish a new connection: [Errno 101] Network is unreachable'))

During handling of the above exception, another exception occurred:

Traceback (most recent call last):
  File "/home/cagri/.local/lib/python3.12/site-packages/wandb/sdk/lib/retry.py", line 134, in __call__
    result = self._call_fn(*args, **kwargs)
             ^^^^^^^^^^^^^^^^^^^^^^^^^^^^^^
  File "/home/cagri/.local/lib/python3.12/site-packages/wandb/sdk/internal/internal_api.py", line 398, in execute
    return self.client.execute(*args, **kwargs)  # type: ignore
           ^^^^^^^^^^^^^^^^^^^^^^^^^^^^^^^^^^^^
  File "/home/cagri/.local/lib/python3.12/site-packages/wandb/vendor/gql-0.2.0/wandb_gql/client.py", line 52, in execute
    result = self._get_result(document, *args, **kwargs)
             ^^^^^^^^^^^^^^^^^^^^^^^^^^^^^^^^^^^^^^^^^^^
  File "/home/cagri/.local/lib/python3.12/site-packages/wandb/vendor/gql-0.2.0/wandb_gql/client.py", line 60, in _get_result
    return self.transport.execute(document, *args, **kwargs)
           ^^^^^^^^^^^^^^^^^^^^^^^^^^^^^^^^^^^^^^^^^^^^^^^^^
  File "/home/cagri/.local/lib/python3.12/site-packages/wandb/sdk/lib/gql_request.py", line 58, in execute
    request = self.session.post(self.url, **post_args)
              ^^^^^^^^^^^^^^^^^^^^^^^^^^^^^^^^^^^^^^^^
  File "/home/cagri/.local/lib/python3.12/site-packages/requests/sessions.py", line 637, in post
    return self.request("POST", url, data=data, json=json, **kwargs)
           ^^^^^^^^^^^^^^^^^^^^^^^^^^^^^^^^^^^^^^^^^^^^^^^^^^^^^^^^^
  File "/home/cagri/.local/lib/python3.12/site-packages/requests/sessions.py", line 589, in request
    resp = self.send(prep, **send_kwargs)
           ^^^^^^^^^^^^^^^^^^^^^^^^^^^^^^
  File "/home/cagri/.local/lib/python3.12/site-packages/requests/sessions.py", line 703, in send
    r = adapter.send(request, **kwargs)
        ^^^^^^^^^^^^^^^^^^^^^^^^^^^^^^^
  File "/home/cagri/.local/lib/python3.12/site-packages/requests/adapters.py", line 700, in send
    raise ConnectionError(e, request=request)
requests.exceptions.ConnectionError: HTTPSConnectionPool(host='api.wandb.ai', port=443): Max retries exceeded with url: /graphql (Caused by NewConnectionError('<urllib3.connection.HTTPSConnection object at 0x70f5acfdc440>: Failed to establish a new connection: [Errno 101] Network is unreachable'))
2025-06-22 22:06:47,403 INFO    MainThread:585317 [wandb_init.py:_post_run_cell_hook():613] [no run ID] resuming backend
2025-06-22 22:07:14,850 INFO    Thread-8 (_run_job):585317 [wandb_run.py:_finish():2321] finishing run e274028-metu-middle-east-technical-university/tinyllama-fewshot/bi9lvl2e
2025-06-22 22:07:14,850 INFO    Thread-8 (_run_job):585317 [jupyter.py:save_history():477] not saving jupyter history
2025-06-22 22:07:14,850 INFO    Thread-8 (_run_job):585317 [jupyter.py:save_ipynb():401] not saving jupyter notebook
2025-06-22 22:07:14,850 INFO    Thread-8 (_run_job):585317 [wandb_init.py:_jupyter_teardown():628] cleaning up jupyter logic
2025-06-22 22:07:14,850 INFO    Thread-8 (_run_job):585317 [wandb_run.py:_atexit_cleanup():2538] got exitcode: 1
2025-06-22 22:07:14,850 INFO    Thread-8 (_run_job):585317 [wandb_run.py:_restore():2520] restore
2025-06-22 22:07:14,850 INFO    Thread-8 (_run_job):585317 [wandb_run.py:_restore():2526] restore done
2025-06-22 22:07:14,851 INFO    Thread-8 (_run_job):585317 [wandb_run.py:_restore():2520] restore
2025-06-22 22:07:14,851 INFO    Thread-8 (_run_job):585317 [wandb_run.py:_restore():2526] restore done
2025-06-22 22:07:14,851 ERROR   Thread-8 (_run_job):585317 [wandb_run.py:_atexit_cleanup():2559] Problem finishing run
Traceback (most recent call last):
  File "/home/cagri/.local/lib/python3.12/site-packages/wandb/agents/pyagent.py", line 306, in _run_job
    self._function()
  File "/tmp/ipykernel_585317/3967257080.py", line 119, in sweep_prompt_eval
    evaluate(test_dataset, model, tokenizer, name="Test")
  File "/tmp/ipykernel_585317/3967257080.py", line 51, in evaluate
    print("Prompt token count:", len(tokenizer(prompt)["input_ids"]))
  File "/home/cagri/.local/lib/python3.12/site-packages/ipykernel/iostream.py", line 694, in write
    self._schedule_flush()
  File "/home/cagri/.local/lib/python3.12/site-packages/ipykernel/iostream.py", line 590, in _schedule_flush
    self.pub_thread.schedule(_schedule_in_thread)
  File "/home/cagri/.local/lib/python3.12/site-packages/ipykernel/iostream.py", line 267, in schedule
    self._event_pipe.send(b"")
  File "/home/cagri/.local/lib/python3.12/site-packages/zmq/sugar/socket.py", line 698, in send
    return super().send(data, flags=flags, copy=copy, track=track)
           ^^^^^^^^^^^^^^^^^^^^^^^^^^^^^^^^^^^^^^^^^^^^^^^^^^^^^^^
  File "_zmq.py", line 1081, in zmq.backend.cython._zmq.Socket.send
  File "_zmq.py", line 1123, in zmq.backend.cython._zmq.Socket.send
  File "_zmq.py", line 1268, in zmq.backend.cython._zmq._check_closed
zmq.error.ZMQError: Socket operation on non-socket

During handling of the above exception, another exception occurred:

Traceback (most recent call last):
  File "/home/cagri/.local/lib/python3.12/site-packages/wandb/sdk/wandb_run.py", line 2550, in _atexit_cleanup
    self._on_finish()
  File "/home/cagri/.local/lib/python3.12/site-packages/wandb/sdk/wandb_run.py", line 2801, in _on_finish
    with progress.progress_printer(
  File "/usr/lib/python3.12/contextlib.py", line 137, in __enter__
    return next(self.gen)
           ^^^^^^^^^^^^^^
  File "/home/cagri/.local/lib/python3.12/site-packages/wandb/sdk/lib/progress.py", line 92, in progress_printer
    with printer.dynamic_text() as text_area:
  File "/usr/lib/python3.12/contextlib.py", line 137, in __enter__
    return next(self.gen)
           ^^^^^^^^^^^^^^
  File "/home/cagri/.local/lib/python3.12/site-packages/wandb/sdk/lib/printer.py", line 465, in dynamic_text
    handle = self._ipython_display.display(
             ^^^^^^^^^^^^^^^^^^^^^^^^^^^^^^
  File "/home/cagri/.local/lib/python3.12/site-packages/IPython/core/display_functions.py", line 285, in display
    publish_display_data(data=format_dict, metadata=md_dict, **kwargs)
  File "/home/cagri/.local/lib/python3.12/site-packages/IPython/core/display_functions.py", line 73, in publish_display_data
    display_pub.publish(
  File "/home/cagri/.local/lib/python3.12/site-packages/ipykernel/zmqshell.py", line 103, in publish
    self._flush_streams()
  File "/home/cagri/.local/lib/python3.12/site-packages/ipykernel/zmqshell.py", line 66, in _flush_streams
    sys.stdout.flush()
  File "/home/cagri/.local/lib/python3.12/site-packages/ipykernel/iostream.py", line 604, in flush
    self.pub_thread.schedule(self._flush)
  File "/home/cagri/.local/lib/python3.12/site-packages/ipykernel/iostream.py", line 267, in schedule
    self._event_pipe.send(b"")
  File "/home/cagri/.local/lib/python3.12/site-packages/zmq/sugar/socket.py", line 698, in send
    return super().send(data, flags=flags, copy=copy, track=track)
           ^^^^^^^^^^^^^^^^^^^^^^^^^^^^^^^^^^^^^^^^^^^^^^^^^^^^^^^
  File "_zmq.py", line 1081, in zmq.backend.cython._zmq.Socket.send
  File "_zmq.py", line 1123, in zmq.backend.cython._zmq.Socket.send
  File "_zmq.py", line 1268, in zmq.backend.cython._zmq._check_closed
zmq.error.ZMQError: Socket operation on non-socket
2025-06-22 22:17:56,887 INFO    MsgRouterThr:585317 [mailbox.py:close():129] [no run ID] Closing mailbox, abandoning 1 handles.
