2025-06-21 11:43:27,901 INFO    Thread-14 (_run_job):309425 [wandb_setup.py:_flush():70] Current SDK version is 0.19.11
2025-06-21 11:43:27,901 INFO    Thread-14 (_run_job):309425 [wandb_setup.py:_flush():70] Configure stats pid to 309425
2025-06-21 11:43:27,901 INFO    Thread-14 (_run_job):309425 [wandb_setup.py:_flush():70] Loading settings from /home/cagri/.config/wandb/settings
2025-06-21 11:43:27,902 INFO    Thread-14 (_run_job):309425 [wandb_setup.py:_flush():70] Loading settings from /home/cagri/Desktop/IS-584-Term-Project/wandb/settings
2025-06-21 11:43:27,902 INFO    Thread-14 (_run_job):309425 [wandb_setup.py:_flush():70] Loading settings from environment variables
2025-06-21 11:43:27,902 INFO    Thread-14 (_run_job):309425 [wandb_init.py:setup_run_log_directory():724] Logging user logs to /home/cagri/Desktop/IS-584-Term-Project/wandb/run-20250621_114327-zs9ktlxf/logs/debug.log
2025-06-21 11:43:27,902 INFO    Thread-14 (_run_job):309425 [wandb_init.py:setup_run_log_directory():725] Logging internal logs to /home/cagri/Desktop/IS-584-Term-Project/wandb/run-20250621_114327-zs9ktlxf/logs/debug-internal.log
2025-06-21 11:43:27,902 INFO    Thread-14 (_run_job):309425 [wandb_init.py:monkeypatch_ipython():643] configuring jupyter hooks <wandb.sdk.wandb_init._WandbInit object at 0x70acb37338f0>
2025-06-21 11:43:27,902 INFO    Thread-14 (_run_job):309425 [wandb_init.py:init():852] calling init triggers
2025-06-21 11:43:27,902 INFO    Thread-14 (_run_job):309425 [wandb_init.py:init():857] wandb.init called with sweep_config: {'learning_rate': 2e-05, 'lora_dropout': 0.1, 'r': 1}
config: {'_wandb': {}}
2025-06-21 11:43:27,902 INFO    Thread-14 (_run_job):309425 [wandb_init.py:init():893] starting backend
2025-06-21 11:43:27,902 INFO    Thread-14 (_run_job):309425 [wandb_init.py:init():897] sending inform_init request
2025-06-21 11:43:27,911 INFO    Thread-14 (_run_job):309425 [backend.py:_multiprocessing_setup():101] multiprocessing start_methods=fork,spawn,forkserver, using: spawn
2025-06-21 11:43:27,911 INFO    Thread-14 (_run_job):309425 [wandb_init.py:init():907] backend started and connected
2025-06-21 11:43:27,914 INFO    Thread-14 (_run_job):309425 [wandb_run.py:_config_callback():1436] config_cb None None {'learning_rate': 2e-05, 'lora_dropout': 0.1, 'r': 1}
2025-06-21 11:43:27,915 INFO    Thread-14 (_run_job):309425 [wandb_run.py:_label_probe_notebook():1376] probe notebook
2025-06-21 11:43:27,916 INFO    Thread-14 (_run_job):309425 [wandb_init.py:init():1005] updated telemetry
2025-06-21 11:43:27,920 INFO    Thread-14 (_run_job):309425 [wandb_init.py:init():1029] communicating run to backend with 90.0 second timeout
2025-06-21 11:43:28,529 INFO    Thread-14 (_run_job):309425 [wandb_init.py:init():1104] starting run threads in backend
2025-06-21 11:43:28,838 INFO    Thread-14 (_run_job):309425 [wandb_run.py:_console_start():2573] atexit reg
2025-06-21 11:43:28,838 INFO    Thread-14 (_run_job):309425 [wandb_run.py:_redirect():2421] redirect: wrap_raw
2025-06-21 11:43:28,838 INFO    Thread-14 (_run_job):309425 [wandb_run.py:_redirect():2490] Wrapping output streams.
2025-06-21 11:43:28,838 INFO    Thread-14 (_run_job):309425 [wandb_run.py:_redirect():2513] Redirects installed.
2025-06-21 11:43:28,838 INFO    Thread-14 (_run_job):309425 [wandb_init.py:init():1150] run started, returning control to user process
2025-06-21 11:43:34,209 INFO    Thread-14 (_run_job):309425 [wandb_run.py:_config_callback():1436] config_cb None None {'output_dir': './results', 'overwrite_output_dir': False, 'do_train': False, 'do_eval': False, 'do_predict': False, 'eval_strategy': 'no', 'prediction_loss_only': False, 'per_device_train_batch_size': 1, 'per_device_eval_batch_size': 1, 'per_gpu_train_batch_size': None, 'per_gpu_eval_batch_size': None, 'gradient_accumulation_steps': 1, 'eval_accumulation_steps': None, 'eval_delay': 0, 'torch_empty_cache_steps': None, 'weight_decay': 0.0, 'adam_beta1': 0.9, 'adam_beta2': 0.999, 'adam_epsilon': 1e-08, 'max_grad_norm': 1.0, 'num_train_epochs': 5, 'max_steps': -1, 'lr_scheduler_type': 'linear', 'lr_scheduler_kwargs': {}, 'warmup_ratio': 0.0, 'warmup_steps': 0, 'log_level': 'passive', 'log_level_replica': 'warning', 'log_on_each_node': True, 'logging_dir': './logs', 'logging_strategy': 'steps', 'logging_first_step': False, 'logging_steps': 100, 'logging_nan_inf_filter': True, 'save_strategy': 'steps', 'save_steps': 500, 'save_total_limit': 1, 'save_safetensors': True, 'save_on_each_node': False, 'save_only_model': False, 'restore_callback_states_from_checkpoint': False, 'no_cuda': False, 'use_cpu': False, 'use_mps_device': False, 'seed': 42, 'data_seed': None, 'jit_mode_eval': False, 'use_ipex': False, 'bf16': False, 'fp16': True, 'fp16_opt_level': 'O1', 'half_precision_backend': 'auto', 'bf16_full_eval': False, 'fp16_full_eval': False, 'tf32': None, 'local_rank': 0, 'ddp_backend': None, 'tpu_num_cores': None, 'tpu_metrics_debug': False, 'debug': [], 'dataloader_drop_last': False, 'eval_steps': None, 'dataloader_num_workers': 0, 'dataloader_prefetch_factor': None, 'past_index': -1, 'run_name': 'term-project', 'disable_tqdm': False, 'remove_unused_columns': True, 'label_names': None, 'load_best_model_at_end': False, 'metric_for_best_model': None, 'greater_is_better': None, 'ignore_data_skip': False, 'fsdp': [], 'fsdp_min_num_params': 0, 'fsdp_config': {'min_num_params': 0, 'xla': False, 'xla_fsdp_v2': False, 'xla_fsdp_grad_ckpt': False}, 'fsdp_transformer_layer_cls_to_wrap': None, 'accelerator_config': {'split_batches': False, 'dispatch_batches': None, 'even_batches': True, 'use_seedable_sampler': True, 'non_blocking': False, 'gradient_accumulation_kwargs': None}, 'deepspeed': None, 'label_smoothing_factor': 0.0, 'optim': 'adamw_torch', 'optim_args': None, 'adafactor': False, 'group_by_length': False, 'length_column_name': 'length', 'report_to': ['wandb'], 'ddp_find_unused_parameters': None, 'ddp_bucket_cap_mb': None, 'ddp_broadcast_buffers': None, 'dataloader_pin_memory': True, 'dataloader_persistent_workers': False, 'skip_memory_metrics': True, 'use_legacy_prediction_loop': False, 'push_to_hub': False, 'resume_from_checkpoint': None, 'hub_model_id': None, 'hub_strategy': 'every_save', 'hub_token': '<HUB_TOKEN>', 'hub_private_repo': None, 'hub_always_push': False, 'gradient_checkpointing': False, 'gradient_checkpointing_kwargs': None, 'include_inputs_for_metrics': False, 'include_for_metrics': [], 'eval_do_concat_batches': True, 'fp16_backend': 'auto', 'push_to_hub_model_id': None, 'push_to_hub_organization': None, 'push_to_hub_token': '<PUSH_TO_HUB_TOKEN>', 'mp_parameters': '', 'auto_find_batch_size': False, 'full_determinism': False, 'torchdynamo': None, 'ray_scope': 'last', 'ddp_timeout': 1800, 'torch_compile': False, 'torch_compile_backend': None, 'torch_compile_mode': None, 'include_tokens_per_second': False, 'include_num_input_tokens_seen': False, 'neftune_noise_alpha': None, 'optim_target_modules': None, 'batch_eval_metrics': False, 'eval_on_start': False, 'use_liger_kernel': False, 'eval_use_gather_object': False, 'average_tokens_across_devices': False}
2025-06-21 16:23:42,278 INFO    Thread-7 (_heartbeat):309425 [retry.py:__call__():175] [no run ID] Retry attempt failed:
Traceback (most recent call last):
  File "/home/cagri/.local/lib/python3.12/site-packages/urllib3/connection.py", line 198, in _new_conn
    sock = connection.create_connection(
           ^^^^^^^^^^^^^^^^^^^^^^^^^^^^^
  File "/home/cagri/.local/lib/python3.12/site-packages/urllib3/util/connection.py", line 60, in create_connection
    for res in socket.getaddrinfo(host, port, family, socket.SOCK_STREAM):
               ^^^^^^^^^^^^^^^^^^^^^^^^^^^^^^^^^^^^^^^^^^^^^^^^^^^^^^^^^^
  File "/usr/lib/python3.12/socket.py", line 963, in getaddrinfo
    for res in _socket.getaddrinfo(host, port, family, type, proto, flags):
               ^^^^^^^^^^^^^^^^^^^^^^^^^^^^^^^^^^^^^^^^^^^^^^^^^^^^^^^^^^^
socket.gaierror: [Errno -3] Temporary failure in name resolution

The above exception was the direct cause of the following exception:

Traceback (most recent call last):
  File "/home/cagri/.local/lib/python3.12/site-packages/urllib3/connectionpool.py", line 787, in urlopen
    response = self._make_request(
               ^^^^^^^^^^^^^^^^^^^
  File "/home/cagri/.local/lib/python3.12/site-packages/urllib3/connectionpool.py", line 488, in _make_request
    raise new_e
  File "/home/cagri/.local/lib/python3.12/site-packages/urllib3/connectionpool.py", line 464, in _make_request
    self._validate_conn(conn)
  File "/home/cagri/.local/lib/python3.12/site-packages/urllib3/connectionpool.py", line 1093, in _validate_conn
    conn.connect()
  File "/home/cagri/.local/lib/python3.12/site-packages/urllib3/connection.py", line 704, in connect
    self.sock = sock = self._new_conn()
                       ^^^^^^^^^^^^^^^^
  File "/home/cagri/.local/lib/python3.12/site-packages/urllib3/connection.py", line 205, in _new_conn
    raise NameResolutionError(self.host, self, e) from e
urllib3.exceptions.NameResolutionError: <urllib3.connection.HTTPSConnection object at 0x70acb38c76e0>: Failed to resolve 'api.wandb.ai' ([Errno -3] Temporary failure in name resolution)

The above exception was the direct cause of the following exception:

Traceback (most recent call last):
  File "/home/cagri/.local/lib/python3.12/site-packages/requests/adapters.py", line 667, in send
    resp = conn.urlopen(
           ^^^^^^^^^^^^^
  File "/home/cagri/.local/lib/python3.12/site-packages/urllib3/connectionpool.py", line 841, in urlopen
    retries = retries.increment(
              ^^^^^^^^^^^^^^^^^^
  File "/home/cagri/.local/lib/python3.12/site-packages/urllib3/util/retry.py", line 519, in increment
    raise MaxRetryError(_pool, url, reason) from reason  # type: ignore[arg-type]
    ^^^^^^^^^^^^^^^^^^^^^^^^^^^^^^^^^^^^^^^^^^^^^^^^^^^
urllib3.exceptions.MaxRetryError: HTTPSConnectionPool(host='api.wandb.ai', port=443): Max retries exceeded with url: /graphql (Caused by NameResolutionError("<urllib3.connection.HTTPSConnection object at 0x70acb38c76e0>: Failed to resolve 'api.wandb.ai' ([Errno -3] Temporary failure in name resolution)"))

During handling of the above exception, another exception occurred:

Traceback (most recent call last):
  File "/home/cagri/.local/lib/python3.12/site-packages/wandb/sdk/lib/retry.py", line 134, in __call__
    result = self._call_fn(*args, **kwargs)
             ^^^^^^^^^^^^^^^^^^^^^^^^^^^^^^
  File "/home/cagri/.local/lib/python3.12/site-packages/wandb/sdk/internal/internal_api.py", line 398, in execute
    return self.client.execute(*args, **kwargs)  # type: ignore
           ^^^^^^^^^^^^^^^^^^^^^^^^^^^^^^^^^^^^
  File "/home/cagri/.local/lib/python3.12/site-packages/wandb/vendor/gql-0.2.0/wandb_gql/client.py", line 52, in execute
    result = self._get_result(document, *args, **kwargs)
             ^^^^^^^^^^^^^^^^^^^^^^^^^^^^^^^^^^^^^^^^^^^
  File "/home/cagri/.local/lib/python3.12/site-packages/wandb/vendor/gql-0.2.0/wandb_gql/client.py", line 60, in _get_result
    return self.transport.execute(document, *args, **kwargs)
           ^^^^^^^^^^^^^^^^^^^^^^^^^^^^^^^^^^^^^^^^^^^^^^^^^
  File "/home/cagri/.local/lib/python3.12/site-packages/wandb/sdk/lib/gql_request.py", line 58, in execute
    request = self.session.post(self.url, **post_args)
              ^^^^^^^^^^^^^^^^^^^^^^^^^^^^^^^^^^^^^^^^
  File "/home/cagri/.local/lib/python3.12/site-packages/requests/sessions.py", line 637, in post
    return self.request("POST", url, data=data, json=json, **kwargs)
           ^^^^^^^^^^^^^^^^^^^^^^^^^^^^^^^^^^^^^^^^^^^^^^^^^^^^^^^^^
  File "/home/cagri/.local/lib/python3.12/site-packages/requests/sessions.py", line 589, in request
    resp = self.send(prep, **send_kwargs)
           ^^^^^^^^^^^^^^^^^^^^^^^^^^^^^^
  File "/home/cagri/.local/lib/python3.12/site-packages/requests/sessions.py", line 703, in send
    r = adapter.send(request, **kwargs)
        ^^^^^^^^^^^^^^^^^^^^^^^^^^^^^^^
  File "/home/cagri/.local/lib/python3.12/site-packages/requests/adapters.py", line 700, in send
    raise ConnectionError(e, request=request)
requests.exceptions.ConnectionError: HTTPSConnectionPool(host='api.wandb.ai', port=443): Max retries exceeded with url: /graphql (Caused by NameResolutionError("<urllib3.connection.HTTPSConnection object at 0x70acb38c76e0>: Failed to resolve 'api.wandb.ai' ([Errno -3] Temporary failure in name resolution)"))
